Workbook

Sheet Tx_croissance
A1: Country Name | B1: Country Code | C1: Series Name | D1: 1995 [YR1995] | E1: 1996 [YR1996] | F1: 1997 [YR1997] | G1: 1998 [YR1998] | H1: 1999 [YR1999] | I1: 2000 [YR2000] | J1: 2001 [YR2001] | K1: 2002 [YR2002] | L1: 2003 [YR2003] | M1: 2004 [YR2004] | N1: 2005 [YR2005] | O1: 2006 [YR2006] | P1: 2007 [YR2007] | Q1: 2008 [YR2008] | R1: 2009 [YR2009] | S1: 2010 [YR2010] | T1: 2011 [YR2011] | U1: 2012 [YR2012] | V1: 2013 [YR2013] | W1: 2014 [YR2014] | X1: 2015 [YR2015] | Y1: 2016 [YR2016] | Z1: 2017 [YR2017] | AA1: 2018 [YR2018] | AB1: 2019 [YR2019] | AC1: 2020 [YR2020] | AD1: 2021 [YR2021] | AE1: 2022 [YR2022]
A2: Afghanistan | B2: AFG | C2: GDP per capita (constant 2015 US$) | D2: .. | E2: .. | F2: .. | G2: .. | H2: .. | I2: .. | J2: .. | K2: 344.22418 | L2: 347.41524 | M2: 338.7394 | N2: 363.54147 | O2: 367.48585 | P2: 410.86161 | Q2: 418.52317 | R2: 490.27284 | S2: 544.6893 | T2: 527.19734 | U2: 570.67606 | V2: 582.10398 | W2: 576.48782 | X2: 566.88113 | Y2: 564.92084 | Z2: 563.48824 | AA2: 553.97331 | AB2: 559.14096 | AC2: 529.14491 | AD2: 407.61651 | AE2: .. | AH2: =IFERROR(((AE2/D2)^(1/27)-1)*100,"NA") -> NA
A3: Albania | B3: ALB | C3: GDP per capita (constant 2015 US$) | D3: 1488.0209 | E3: 1633.552 | F3: 1464.298 | G3: 1603.6477 | H3: 1821.8731 | I3: 1960.8825 | J3: 2143.5268 | K3: 2247.4981 | L3: 2380.6446 | M3: 2522.4494 | N3: 2675.5086 | O3: 2851.3678 | P3: 3044.8966 | Q3: 3298.4789 | R3: 3432.1709 | S3: 3577.1143 | T3: 3678.0477 | U3: 3736.3401 | V3: 3780.6992 | W3: 3855.7607 | X3: 3952.8036 | Y3: 4090.3727 | Z3: 4249.82 | AA3: 4431.5556 | AB3: 4543.3877 | AC3: 4418.6609 | AD3: 4857.1119 | AE3: 5155.2909 | AH3: =IFERROR(((AE3/D3)^(1/27)-1)*100,"NA") -> 4.7096771
A4: Algeria | B4: DZA | C4: GDP per capita (constant 2015 US$) | D4: 2862.1079 | E4: 2927.3774 | F4: 2910.2392 | G4: 3012.8054 | H4: 3066.0377 | I4: 3138.23 | J4: 3188.2062 | K4: 3321.6378 | L4: 3512.899 | M4: 3612.753 | N4: 3774.0713 | O4: 3783.313 | P4: 3848.7783 | Q4: 3874.3681 | R4: 3866.2958 | S4: 3931.7201 | T4: 3969.6603 | U4: 4025.6415 | V4: 4057.7648 | W4: 4129.4225 | X4: 4197.42 | Y4: 4246.2422 | Z4: 4218.0823 | AA4: 4188.2204 | AB4: 4153.0035 | AC4: 3873.5087 | AD4: 3939.3609 | AE4: 3999.7577 | AH4: =IFERROR(((AE4/D4)^(1/27)-1)*100,"NA") -> 1.2472527
A5: American Samoa | B5: ASM | C5: GDP per capita (constant 2015 US$) | D5: .. | E5: .. | F5: .. | G5: .. | H5: .. | I5: .. | J5: .. | K5: 12804.436 | L5: 12980.722 | M5: 13105.169 | N5: 13136.48 | O5: 12690.529 | P5: 13029.616 | Q5: 12795.025 | R5: 12378.17 | S5: 12532.311 | T5: 12656.688 | U5: 12247.635 | V5: 12098.275 | W5: 12494.98 | X5: 13101.542 | Y5: 13116.431 | Z5: 12442.858 | AA5: 13049.33 | AB5: 13288.357 | AC5: 14214.646 | AD5: 14464.814 | AE5: 14969.06 | AH5: =IFERROR(((AE5/D5)^(1/27)-1)*100,"NA") -> NA
A6: Andorra | B6: AND | C6: GDP per capita (constant 2015 US$) | D6: 28051.403 | E6: 28797.867 | F6: 31149.37 | G6: 31895.996 | H6: 32966.252 | I6: 33901.193 | J6: 35722.546 | K6: 35749.946 | L6: 37250.313 | M6: 38696.513 | N6: 39307.159 | O6: 40994.467 | P6: 42724.587 | Q6: 41470.457 | R6: 40442.804 | S6: 40937.293 | T6: 41486.219 | U6: 39174.916 | V6: 37597.723 | W6: 38402.667 | X6: 38885.549 | Y6: 39886.659 | Z6: 39321.633 | AA6: 39320.111 | AB6: 39413.809 | AC6: 34394.43 | AD6: 36616.118 | AE6: 39447.538 | AH6: =IFERROR(((AE6/D6)^(1/27)-1)*100,"NA") -> 1.2707207
A7: Angola | B7: AGO | C7: GDP per capita (constant 2015 US$) | D7: 1675.7081 | E7: 1840.3541 | F7: 1909.4689 | G7: 1934.558 | H7: 1913.9989 | I7: 1909.5021 | J7: 1925.508 | K7: 2116.8517 | L7: 2106.9859 | M7: 2257.1524 | N7: 2505.655 | O7: 2696.4411 | P7: 2964.3355 | Q7: 3176.6722 | R7: 3087.8114 | S7: 3105.4497 | T7: 3094.7339 | U7: 3235.1746 | V7: 3270.9663 | W7: 3304.6812 | X7: 3217.3392 | Y7: 3023.9163 | Z7: 2914.1271 | AA7: 2777.843 | AB7: 2666.2539 | AC7: 2435.0249 | AD7: 2387.4299 | AE7: 2385.12 | AH7: =IFERROR(((AE7/D7)^(1/27)-1)*100,"NA") -> 1.3160424
A8: Antigua and Barbuda | B8: ATG | C8: GDP per capita (constant 2015 US$) | D8: 13584.273 | E8: 14190.974 | F8: 14669.016 | G8: 15076.393 | H8: 15370.828 | I8: 16055.954 | J8: 15092.469 | K8: 15053.966 | L8: 15788.74 | M8: 16516.087 | N8: 17380.986 | O8: 19341.328 | P8: 20854.062 | Q8: 20541.753 | R8: 17809.933 | S8: 16191.157 | T8: 15684.781 | U8: 15739.035 | V8: 15668.436 | W8: 15882.309 | X8: 15985.541 | Y8: 16526.436 | Z8: 16830.396 | AA8: 17901.041 | AB8: 18357.679 | AC8: 14803.77 | AD8: 15921.095 | AE8: 17335.047 | AH8: =IFERROR(((AE8/D8)^(1/27)-1)*100,"NA") -> 0.90711749
A9: Argentina | B9: ARG | C9: GDP per capita (constant 2015 US$) | D9: 9969.3316 | E9: 10388.539 | F9: 11097.382 | G9: 11391.945 | H9: 10880.206 | I9: 10672.722 | J9: 10090.653 | K9: 8895.3196 | L9: 9581.9698 | M9: 10341.643 | N9: 11141.311 | O9: 11913.959 | P9: 12857.093 | Q9: 13246.635 | R9: 12336.862 | S9: 13551.339 | T9: 14200.27 | U9: 13895.634 | V9: 14071.509 | W9: 13567.948 | X9: 13789.06 | Y9: 13360.212 | Z9: 13595.037 | AA9: 13105.397 | AB9: 12716.224 | AC9: 11346.652 | AD9: 12444.318 | AE9: 12940.738 | AH9: =IFERROR(((AE9/D9)^(1/27)-1)*100,"NA") -> 0.97085591
A10: Armenia | B10: ARM | C10: GDP per capita (constant 2015 US$) | D10: 928.0925 | E10: 989.64234 | F10: 1031.0983 | G10: 1116.9072 | H10: 1166.188 | I10: 1249.6121 | J10: 1385.0448 | K10: 1582.0576 | L10: 1815.7882 | M10: 2018.4601 | N10: 2312.9829 | O10: 2636.2566 | P10: 3019.4656 | Q10: 3250.4986 | R10: 2810.1928 | S10: 2889.5662 | T10: 3043.2628 | U10: 3278.6704 | V10: 3402.0839 | W10: 3538.5294 | X10: 3666.1418 | Y10: 3689.8301 | Z10: 3985.9167 | AA10: 4215.8994 | AB10: 4561.9678 | AC10: 4256.1312 | AD10: 4526.5975 | AE10: 5116.2058 | AH10: =IFERROR(((AE10/D10)^(1/27)-1)*100,"NA") -> 6.5264997
A11: Aruba | B11: ABW | C11: GDP per capita (constant 2015 US$) | D11: 29497.963 | E11: 28958.144 | F11: 30074.406 | G11: 29765.515 | H11: 29262.616 | I11: 30703.661 | J11: 31426.879 | K11: 30760.207 | L11: 30793.135 | M11: 32742.761 | N11: 32291.769 | O11: 32272.251 | P11: 32863.362 | Q11: 33053.767 | R11: 28836.017 | S11: 27732.214 | T11: 28398.558 | U11: 27876.206 | V11: 29447.58 | W11: 28780.631 | X11: 28419.265 | Y11: 28737.896 | Z11: 30598.649 | AA11: 31172.802 | AB11: 30317.607 | AC11: 23015.742 | AD11: 29390.381 | AE11: 32492.179 | AH11: =IFERROR(((AE11/D11)^(1/27)-1)*100,"NA") -> 0.35870917
A12: Australia | B12: AUS | C12: GDP per capita (constant 2015 US$) | D12: 39309.995 | E12: 40336.299 | F12: 41463.646 | G12: 42966.793 | H12: 44636.024 | I12: 45858.58 | J12: 46190.381 | K12: 47485.341 | L12: 48393.137 | M12: 49901.015 | N12: 50852.161 | O12: 51552.894 | P12: 52530.702 | Q12: 53335.006 | R12: 53235.924 | S12: 53581.159 | T12: 54114.726 | U12: 55261.918 | V12: 55734.574 | W12: 56341.134 | X12: 56758.869 | Y12: 57432.18 | Z12: 57804.051 | AA12: 58600.79 | AB12: 59000.735 | AC12: 58082.427 | AD12: 59225.525 | AE12: 60993.641 | AH12: =IFERROR(((AE12/D12)^(1/27)-1)*100,"NA") -> 1.6403108
A13: Austria | B13: AUT | C13: GDP per capita (constant 2015 US$) | D13: 33790.485 | E13: 34537.74 | F13: 35220.888 | G13: 36442.288 | H13: 37664.943 | I13: 38842.891 | J13: 39184.809 | K13: 39636.483 | L13: 39815.222 | M13: 40651.227 | N13: 41281.271 | O13: 42496.351 | P13: 43937.713 | Q13: 44440.056 | R13: 42655.192 | S13: 43334.509 | T13: 44451 | U13: 44549.882 | V13: 44299.378 | W13: 44245.169 | X13: 44195.818 | Y13: 44590.252 | Z13: 45281.723 | AA13: 46154.625 | AB13: 46616.359 | AC13: 43343.972 | AD13: 44984.42 | AE13: 46697.857 | AH13: =IFERROR(((AE13/D13)^(1/27)-1)*100,"NA") -> 1.205426
A14: Azerbaijan | B14: AZE | C14: GDP per capita (constant 2015 US$) | D14: 1102.4979 | E14: 1105.5872 | F14: 1158.4817 | G14: 1262.2919 | H14: 1343.8559 | I14: 1480.8087 | J14: 1614.8489 | K14: 1754.1352 | L14: 1918.611 | M14: 2077.8853 | N14: 2631.8515 | O14: 3501.1648 | P14: 4327.1136 | Q14: 4693.0771 | R14: 5023.9673 | S14: 5215.2042 | T14: 5152.8385 | U14: 5194.9209 | V14: 5426.0959 | W14: 5506.1817 | X14: 5500.5036 | Y14: 5270.7382 | Z14: 5229.7099 | AA14: 5262.3687 | AB14: 5348.4532 | AC14: 5083.5603 | AD14: 5345.4399 | AE14: 5590.0044 | AH14: =IFERROR(((AE14/D14)^(1/27)-1)*100,"NA") -> 6.1970333
A15: Bahamas, The | B15: BHS | C15: GDP per capita (constant 2015 US$) | D15: 28410.556 | E15: 29088.157 | F15: 28965.19 | G15: 29828.746 | H15: 31473.369 | I15: 32300.766 | J15: 32685.179 | K15: 33129.484 | L15: 32276.72 | M15: 32125.044 | N15: 32765.745 | O15: 33127.423 | P15: 33136.488 | Q15: 31908.932 | R15: 30139.453 | S15: 30175.639 | T15: 29984.884 | U15: 30577.734 | V15: 29426.023 | W15: 29701.458 | X15: 29724.953 | Y15: 29253.891 | Z15: 29763.505 | AA15: 30412.133 | AB15: 29988.165 | AC15: 22830.504 | AD15: 26614.19 | AE15: 30283.897 | AH15: =IFERROR(((AE15/D15)^(1/27)-1)*100,"NA") -> 0.2367812
A16: Bahrain | B16: BHR | C16: GDP per capita (constant 2015 US$) | D16: 20403.371 | E16: 20576.515 | F16: 20566.557 | G16: 20915.833 | H16: 21195.901 | I16: 21713.538 | J16: 21681.028 | K16: 21866.049 | L16: 22348.905 | M16: 22325.703 | N16: 22027.331 | O16: 21783.852 | P16: 22013.758 | Q16: 21918.005 | R16: 21157.793 | S16: 21452.922 | T16: 21906.746 | U16: 22484.855 | V16: 23012.708 | W16: 23107.957 | X16: 22795.449 | Y16: 22810.775 | Z16: 23019.256 | AA16: 23023.12 | AB16: 23414.219 | AC16: 22579.362 | AD16: 23407.196 | AE16: 24395.472 | AH16: =IFERROR(((AE16/D16)^(1/27)-1)*100,"NA") -> 0.66403743
A17: Bangladesh | B17: BGD | C17: GDP per capita (constant 2015 US$) | D17: 559.68923 | E17: 574.83582 | F17: 590.00279 | G17: 609.01356 | H17: 625.36385 | I17: 646.03776 | J17: 666.06776 | K17: 678.86751 | L17: 698.73209 | M17: 723.22784 | N17: 758.88997 | O17: 799.78147 | P17: 847.28195 | Q17: 890.29617 | R17: 927.01809 | S17: 967.56108 | T17: 1017.6277 | U17: 1070.5952 | V17: 1120.6853 | W17: 1173.893 | X17: 1236.0044 | Y17: 1307.7323 | Z17: 1376.6035 | AA17: 1460.3042 | AB17: 1557.9643 | AC17: 1593.3474 | AD17: 1684.4335 | AE17: 1784.7389 | AH17: =IFERROR(((AE17/D17)^(1/27)-1)*100,"NA") -> 4.3885534
... A23: Bermuda | B23: BMU | C23: GDP per capita (constant 2015 US$) | D23: 89518.278 | E23: 91261.151 | F23: 94878.492 | G23: 97857.323 | H23: 100602.93 | I23: 109001.59 | J23: 115619.47 | K23: 113172.12 | L23: 116268.82 | M23: 118193.15 | N23: 119396.45 | O23: 125294.96 | P23: 128757.88 | Q23: 125610.03 | R23: 117886.74 | S23: 115839.8 | T23: 112471.35 | U23: 106119.8 | V23: 105492.48 | W23: 101374.47 | X23: 102005.63 | Y23: 102407.39 | Z23: 107237.03 | AA23: 106697.74 | AB23: 107036.24 | AC23: 99745.242 | AD23: 102959.25 | AE23: 106359.97 | AH23: =IFERROR(((AE23/D23)^(1/27)-1)*100,"NA") -> 0.64051094
A24: Bhutan | B24: BTN | C24: GDP per capita (constant 2015 US$) | D24: 944.40756 | E24: 978.49497 | F24: 1013.4093 | G24: 1053.542 | H24: 1110.0673 | I24: 1115.6253 | J24: 1176.6533 | K24: 1272.6318 | L24: 1338.5086 | M24: 1385.3964 | N24: 1456.4798 | O24: 1535.4279 | P24: 1795.0718 | Q24: 1859.0704 | R24: 1961.9388 | S24: 2171.9098 | T24: 2319.5909 | U24: 2411.8964 | V24: 2436.8598 | W24: 2551.4831 | X24: 2695.6369 | Y24: 2889.4939 | Z24: 2998.4732 | AA24: 3079.144 | AB24: 3233.5979 | AC24: 2884.2087 | AD24: 2992.4393 | AE24: .. | AH24: =IFERROR(((AE24/D24)^(1/27)-1)*100,"NA") -> NA
A25: Bolivia | B25: BOL | C25: GDP per capita (constant 2015 US$) | D25: 1866.6529 | E25: 1912.0023 | F25: 1970.1681 | G25: 2031.9722 | H25: 2003.8613 | I25: 2017.3946 | J25: 2015.3775 | K25: 2029.6179 | L25: 2048.5598 | M25: 2097.2584 | N25: 2152.362 | O25: 2216.5447 | P25: 2277.5038 | Q25: 2376.0781 | R25: 2414.1299 | S25: 2471.4736 | T25: 2556.8303 | U25: 2643.6908 | V25: 2777.7205 | W25: 2882.8069 | X25: 2975.6488 | Y25: 3054.8925 | Z25: 3135.0316 | AA25: 3219.2009 | AB25: 3242.9488 | AC25: 2920.1974 | AD25: 3061.8993 | AE25: 3134.7663 | AH25: =IFERROR(((AE25/D25)^(1/27)-1)*100,"NA") -> 1.9385795
A26: Bosnia and Herzegovina | B26: BIH | C26: GDP per capita (constant 2015 US$) | D26: 784.6187 | E26: 1422.9465 | F26: 1846.1525 | G26: 2099.2434 | H26: 2279.7437 | I26: 2554.5641 | J26: 2606.7504 | K26: 2735.5353 | L26: 2851.2736 | M26: 3061.5514 | N26: 3218.5942 | O26: 3423.124 | P26: 3669.0168 | Q26: 3932.0153 | R26: 3878.4405 | S26: 3980.4423 | T26: 4091.5819 | U26: 4133.9027 | V26: 4297.4935 | W26: 4403.6739 | X26: 4654.6086 | Y26: 4865.3513 | Z26: 5082.9973 | AA26: 5339.4771 | AB26: 5558.0814 | AC26: 5459.2196 | AD26: 5947.8193 | AE26: 6263.7021 | AH26: =IFERROR(((AE26/D26)^(1/27)-1)*100,"NA") -> 7.9975228
A27: Botswana | B27: BWA | C27: GDP per capita (constant 2015 US$) | D27: 4271.4709 | E27: 4410.3889 | F27: 4667.8859 | G27: 4585.6741 | H27: 4922.3739 | I27: 4917.2321 | J27: 4831.7838 | K27: 5030.2652 | L27: 5171.5413 | M27: 5219.4145 | N27: 5360.0192 | O27: 5700.2199 | P27: 5913.0699 | Q27: 5982.662 | R27: 5031.9836 | S27: 5428.2962 | T27: 5684.3579 | U27: 5566.6818 | V27: 6067.9984 | W27: 6291.2718 | X27: 5869.7376 | Y27: 6166.2399 | Z27: 6287.8347 | AA27: 6418.7064 | AB27: 6485.5682 | AC27: 5810.8985 | AD27: 6395.1397 | AE27: 6657.5851 | AH27: =IFERROR(((AE27/D27)^(1/27)-1)*100,"NA") -> 1.6572815
A28: Brazil | B28: BRA | C28: GDP per capita (constant 2015 US$) | D28: 6524.5189 | E28: 6567.3525 | F28: 6689.1994 | G28: 6613.9832 | H28: 6551.2267 | I28: 6745.8578 | J28: 6749.8816 | K28: 6868.6959 | L28: 6865.1733 | M28: 7178.3475 | N28: 7325.9036 | O28: 7534.5425 | P28: 7909.8252 | Q28: 8231.1004 | R28: 8142.761 | S28: 8673.8984 | T28: 8935.2773 | U28: 9025.314 | V28: 9216.1323 | W28: 9183.4597 | X28: 8783.2154 | Y28: 8426.8432 | Z28: 8470.9406 | AA28: 8553.8659 | AB28: 8592.2112 | AC28: 8255.568 | AD28: 8621.7316 | AE28: 8831.1277 | AH28: =IFERROR(((AE28/D28)^(1/27)-1)*100,"NA") -> 1.1274772
A29: British Virgin Islands | B29: VGB | C29: GDP per capita (constant 2015 US$) | D29: .. | E29: .. | F29: .. | G29: .. | H29: .. | I29: .. | J29: .. | K29: .. | L29: .. | M29: .. | N29: .. | O29: .. | P29: .. | Q29: .. | R29: .. | S29: .. | T29: .. | U29: .. | V29: .. | W29: .. | X29: .. | Y29: .. | Z29: .. | AA29: .. | AB29: .. | AC29: .. | AD29: .. | AE29: .. | AH29: =IFERROR(((AE29/D29)^(1/27)-1)*100,"NA") -> NA
A30: Brunei Darussalam | B30: BRN | C30: GDP per capita (constant 2015 US$) | D30: 35515.843 | E30: 35690.985 | F30: 34377.858 | G30: 33445.121 | H30: 33739.494 | I30: 33985.815 | J30: 34219.311 | K30: 34857.393 | L30: 35202.789 | M30: 34750.574 | N30: 34290.111 | O30: 35213.218 | P30: 34714.54 | Q30: 33526.003 | R30: 32449.83 | S30: 32810.504 | T30: 33577.06 | U30: 33456.265 | V30: 32341.889 | W30: 31155.744 | X30: 30681.434 | Y30: 29601.097 | Z30: 29695.881 | AA30: 29437.865 | AB30: 30313.414 | AC30: 30401.844 | AD30: 29673.166 | AE30: 28954.064 | AH30: =IFERROR(((AE30/D30)^(1/27)-1)*100,"NA") -> -0.75369466
A31: Bulgaria | B31: BGR | C31: GDP per capita (constant 2015 US$) | D31: 4025.6458 | E31: 4257.0951 | F31: 3678.5166 | G31: 3843.4622 | H31: 3540.5561 | I31: 3721.3035 | J31: 3941.2757 | K31: 4264.2717 | L31: 4523.2862 | M31: 4854.2734 | N31: 5236.0864 | O31: 5634.9112 | P31: 6054.2325 | Q31: 6470.5897 | R31: 6294.4334 | S31: 6434.5524 | T31: 6611.3038 | U31: 6699.503 | V31: 6700.536 | W31: 6802.7103 | X31: 7078.8603 | Y31: 7344.4435 | Z31: 7601.4385 | AA31: 7862.8618 | AB31: 8237.9268 | AC31: 7958.8268 | AD31: 8638.7184 | AE31: 9550.9425 | AH31: =IFERROR(((AE31/D31)^(1/27)-1)*100,"NA") -> 3.2515765
A32: Burkina Faso | B32: BFA | C32: GDP per capita (constant 2015 US$) | D32: 355.98794 | E32: 385.2292 | F32: 399.185 | G32: 416.7417 | H32: 434.65839 | I32: 429.84737 | J32: 444.54975 | K32: 449.85393 | L32: 470.12958 | M32: 476.00998 | N32: 501.20725 | O32: 516.17677 | P32: 521.34526 | Q32: 535.58364 | R32: 535.51683 | S32: 563.92678 | T32: 583.67948 | U32: 602.78676 | V32: 618.80458 | W32: 626.62625 | X32: 632.12669 | Y32: 650.41726 | Z32: 671.2518 | AA32: 696.04457 | AB32: 714.646 | AC32: 709.05775 | AD32: 738.41866 | AE32: 732.57032 | AH32: =IFERROR(((AE32/D32)^(1/27)-1)*100,"NA") -> 2.7088643
A33: Burundi | B33: BDI | C33: GDP per capita (constant 2015 US$) | D33: 354.11618 | E33: 325.91192 | F33: 321.08969 | G33: 330.12893 | H33: 319.1358 | I33: 310.00671 | J33: 308.6452 | K33: 313.48641 | L33: 300.08615 | M33: 303.11967 | N33: 294.73877 | O33: 299.76912 | P33: 298.93666 | Q33: 300.84135 | R33: 296.84709 | S33: 297.79173 | T33: 299.01718 | U33: 301.48132 | V33: 305.29084 | W33: 307.76553 | X33: 289.35963 | Y33: 282.97597 | Z33: 277.9598 | AA33: 274.13191 | AB33: 270.13728 | AC33: 263.36099 | AD33: 264.36483 | AE33: 262.1848 | AH33: =IFERROR(((AE33/D33)^(1/27)-1)*100,"NA") -> -1.1070687
A34: Cabo Verde | B34: CPV | C34: GDP per capita (constant 2015 US$) | D34: 1268.678 | E34: 1380.3336 | F34: 1499.4465 | G34: 1650.4974 | H34: 1797.2957 | I34: 2015.3814 | J34: 2026.2792 | K34: 2099.9002 | L34: 2156.3479 | M34: 2344.5188 | N34: 2474.8249 | O34: 2639.9627 | P34: 3005.2294 | Q34: 3181.4508 | R34: 3101.3938 | S34: 3124.5721 | T34: 3208.3671 | U34: 3204.6019 | V34: 3188.5697 | W34: 3174.7053 | X34: 3169.0789 | Y34: 3267.879 | Z34: 3376.9383 | AA34: 3463.8128 | AB34: 3667.0574 | AC34: 2876.1534 | AD34: 3010.3456 | AE34: 3494.5692 | AH34: =IFERROR(((AE34/D34)^(1/27)-1)*100,"NA") -> 3.8240248
A35: Cambodia | B35: KHM | C35: GDP per capita (constant 2015 US$) | D35: 378.92238 | E35: 391.82902 | F35: 398.65296 | G35: 408.82253 | H35: 451.86145 | I35: 488.0027 | J35: 518.38429 | K35: 542.65474 | L35: 578.40936 | M35: 627.00821 | N35: 697.74676 | O35: 759.64339 | P35: 822.75409 | Q35: 863.38697 | R35: 851.20302 | S35: 888.91259 | T35: 938.01768 | U35: 992.1346 | V35: 1049.9945 | W35: 1109.3757 | X35: 1170.7428 | Y35: 1235.3234 | Z35: 1304.5494 | AA35: 1384.968 | AB35: 1465.9695 | AC35: 1404.1987 | AD35: 1429.937 | AE35: 1488.8146 | AH35: =IFERROR(((AE35/D35)^(1/27)-1)*100,"NA") -> 5.1987922
A36: Cameroon | B36: CMR | C36: GDP per capita (constant 2015 US$) | D36: 1049.7067 | E36: 1064.646 | F36: 1083.6416 | G36: 1105.2452 | H36: 1124.9005 | I36: 1137.6245 | J36: 1156.0504 | K36: 1175.8717 | L36: 1206.6105 | M36: 1256.6936 | N36: 1250.0589 | O36: 1262.8719 | P36: 1281.3925 | Q36: 1281.0198 | R36: 1277.1816 | S36: 1277.2657 | T36: 1283.567 | U36: 1305.668 | V36: 1332.86 | W36: 1366.9666 | X36: 1399.6753 | Y36: 1420.0299 | Z36: 1429.2347 | AA36: 1445.2678 | AB36: 1454.5641 | AC36: 1419.3282 | AD36: 1428.5626 | AE36: 1441.7949 | AH36: =IFERROR(((AE36/D36)^(1/27)-1)*100,"NA") -> 1.1824101
A37: Canada | B37: CAN | C37: GDP per capita (constant 2015 US$) | D37: 32612.232 | E37: 32795.665 | F37: 33861.147 | G37: 34889.671 | H37: 36393.964 | I37: 37923.486 | J37: 38185.22 | K37: 38912.21 | L37: 39257.762 | M37: 40093.807 | N37: 40989.527 | O37: 41646.415 | P37: 42098.431 | Q37: 42063.24 | R37: 40368.932 | S37: 41156.145 | T37: 42037.519 | U37: 42315.807 | V37: 42846.284 | W37: 43635.095 | X37: 43596.136 | Y37: 43536.913 | Z37: 44325.488 | AA37: 44917.484 | AB37: 45113.066 | AC37: 42366.487 | AD37: 44234.542 | AE37: 44928.589 | AH37: =IFERROR(((AE37/D37)^(1/27)-1)*100,"NA") -> 1.1936863
A38: Cayman Islands | B38: CYM | C38: GDP per capita (constant 2015 US$) | D38: .. | E38: .. | F38: .. | G38: .. | H38: .. | I38: .. | J38: .. | K38: .. | L38: .. | M38: .. | N38: .. | O38: 96176.301 | P38: 96280.247 | Q38: 93166.316 | R38: 84026.972 | S38: 79519.845 | T38: 78393.737 | U38: 77448.51 | V38: 76617.544 | W38: 76872.581 | X38: 77295.845 | Y38: 78077.434 | Z38: 78883.281 | AA38: 80597.709 | AB38: 82170.593 | AC38: 76609.769 | AD38: 78731.148 | AE38: 80946.966 | AH38: =IFERROR(((AE38/D38)^(1/27)-1)*100,"NA") -> NA
A39: Central African Republic | B39: CAF | C39: GDP per capita (constant 2015 US$) | D39: 478.34389 | E39: 447.35063 | F39: 458.13384 | G39: 466.63411 | H39: 470.16836 | I39: 445.80329 | J39: 455.33838 | K39: 461.49809 | L39: 426.15958 | M39: 442.01524 | N39: 436.10027 | O39: 447.80811 | P39: 459.74607 | Q39: 459.56246 | R39: 488.38803 | S39: 500.52928 | T39: 513.59427 | U39: 534.88356 | V39: 338.16571 | W39: 338.70038 | X39: 351.87975 | Y39: 362.21833 | Z39: 371.60313 | AA39: 378.26308 | AB39: 381.41405 | AC39: 375.21692 | AD39: 370.98037 | AE39: 364.69075 | AH39: =IFERROR(((AE39/D39)^(1/27)-1)*100,"NA") -> -0.99971073
A40: Chad | B40: TCD | C40: GDP per capita (constant 2015 US$) | D40: 399.99949 | E40: 391.17302 | F40: 399.38814 | G40: 412.84313 | H40: 396.01183 | I40: 379.35155 | J40: 409.70367 | K40: 429.42697 | L40: 473.46802 | M40: 605.23935 | N40: 682.35387 | O40: 662.88551 | P40: 661.77236 | Q40: 658.87446 | R40: 662.92325 | S40: 727.52495 | T40: 703.12322 | U40: 739.33836 | V40: 754.17181 | W40: 777.93568 | X40: 774.4116 | Y40: 703.46601 | Z40: 660.12613 | AA40: 653.34976 | AB40: 652.70322 | AC40: 622.27851 | AD40: 595.66379 | AE40: 590.30518 | AH40: =IFERROR(((AE40/D40)^(1/27)-1)*100,"NA") -> 1.4518322
A41: Channel Islands | B41: CHI | C41: GDP per capita (constant 2015 US$) | D41: .. | E41: .. | F41: .. | G41: .. | H41: .. | I41: .. | J41: .. | K41: .. | L41: .. | M41: .. | N41: .. | O41: .. | P41: .. | Q41: .. | R41: .. | S41: .. | T41: .. | U41: .. | V41: .. | W41: .. | X41: .. | Y41: .. | Z41: .. | AA41: .. | AB41: .. | AC41: .. | AD41: .. | AE41: .. | AH41: =IFERROR(((AE41/D41)^(1/27)-1)*100,"NA") -> NA
A42: Chile | B42: CHL | C42: GDP per capita (constant 2015 US$) | D42: 7277.5619 | E42: 7666.9848 | F42: 8125.9555 | G42: 8359.8749 | H42: 8238.301 | I42: 8549.0791 | J42: 8720.9101 | K42: 8902.838 | L42: 9226.1505 | M42: 9744.3224 | N42: 10212.782 | O42: 10725.055 | P42: 11169.287 | Q42: 11477.09 | R42: 11232.823 | S42: 11770.757 | T42: 12380.015 | U42: 13014.582 | V42: 13316.052 | W42: 13418.976 | X42: 13567.357 | Y42: 13642.018 | Z42: 13612.924 | AA42: 13904.115 | AB42: 13758.747 | AC42: 12738.725 | AD42: 14093.091 | AE42: 14355.606 | AH42: =IFERROR(((AE42/D42)^(1/27)-1)*100,"NA") -> 2.548012
A43: China | B43: CHN | C43: GDP per capita (constant 2015 US$) | D43: 1520.0295 | E43: 1653.4338 | F43: 1787.767 | G43: 1909.6223 | H43: 2038.2065 | I43: 2193.8969 | J43: 2359.5724 | K43: 2557.8916 | L43: 2797.1767 | M43: 3061.8332 | N43: 3390.7162 | O43: 3800.7658 | P43: 4319.0314 | Q43: 4711.6434 | R43: 5128.9041 | S43: 5647.0687 | T43: 6152.6969 | U43: 6591.6625 | V43: 7056.4231 | W43: 7532.7853 | X43: 8016.4456 | Y43: 8516.5287 | Z43: 9053.2287 | AA43: 9619.2095 | AB43: 10155.511 | AC43: 10358.17 | AD43: 11223.255 | AE43: 11560.242 | AH43: =IFERROR(((AE43/D43)^(1/27)-1)*100,"NA") -> 7.8037544
A44: Colombia | B44: COL | C44: GDP per capita (constant 2015 US$) | D44: 4170.4577 | E44: 4179.2262 | F44: 4246.1567 | G44: 4196.9203 | H44: 3953.73 | I44: 4003.9852 | J44: 4007.528 | K44: 4045.3067 | L44: 4142.0077 | M44: 4301.035 | N44: 4447.5668 | O44: 4685.0546 | P44: 4939.118 | Q44: 5042.0611 | R44: 5042.145 | S44: 5209.7325 | T44: 5511.0999 | U44: 5667.4988 | V44: 5899.7679 | W44: 6107.083 | X44: 6228.6516 | Y44: 6291.0797 | Z44: 6280.8911 | AA44: 6320.9907 | AB44: 6404.1088 | AC44: 5852.9832 | AD44: 6423.8599 | AE44: 6842.5325 | AH44: =IFERROR(((AE44/D44)^(1/27)-1)*100,"NA") -> 1.8507405
A45: Comoros | B45: COM | C45: GDP per capita (constant 2015 US$) | D45: 1135.1349 | E45: 1096.6072 | F45: 1116.5306 | G45: 1106.9033 | H45: 1105.7367 | I45: 1202.1314 | J45: 1205.5092 | K45: 1208.5899 | L45: 1210.0285 | M45: 1209.8631 | N45: 1219.9912 | O45: 1227.4829 | P45: 1212.7517 | Q45: 1235.6528 | R45: 1249.8394 | S45: 1270.3027 | T45: 1295.2044 | U45: 1307.973 | V45: 1337.3977 | W45: 1336.4897 | X45: 1322.9368 | Y45: 1337.5279 | Z45: 1360.4312 | AA45: 1383.3779 | AB45: 1381.6222 | AC45: 1352.9555 | AD45: 1355.5388 | AE45: 1362.778 | AH45: =IFERROR(((AE45/D45)^(1/27)-1)*100,"NA") -> 0.67923634
...

Sheet DONNEES
B1: tx croiss | C1: loggdp95 | D1: INV | E1: tx_pop | F1: GOVeff | G1: ESP VIE | H1: POLSTAB | I1: SCOLPRIM | J1: SCOLSEC | K1: SCOLTER | L1: CONTRCORR | M1: RegQual | N1: RuLaw | O1: VoiceAcc | P1: GDP 1995 | Q1: tx_rev_gdp | R1: tx_ipc (%toltx) | S1: profit tx | T1: tx_ipc(%rev) | U1: debt | V1: VAT_gdp | W1: trade_tx_gdp | X1: tx_ipc_gdp | Y1: tx95_rev_gdp | Z1: inv95 | AA1: GNQ | AB1: FMR | AC1: CUS_EX_RT
A2: Afghanistan | B2: =Tx_croissance!AH2 -> NA | C2: =IFERROR(LN(P2),"NA") -> NA | D2: 12.221166 | E2: 3.4954979 | F2: -1.5282862 | G2: 59.095889 | H2: -2.4809625 | I2: 115.7132 | J2: 100.72019 | K2: 29.139934 | L2: -1.4200903 | M2: -1.4936953 | N2: -1.7212338 | O2: -1.3154747 | P2: NA | Q2: 7.8005405 | R2: 28.969577 | S2: 0 | T2: 3.8070328 | U2: NA | V2: ='VATtax et trade tax et ipc '!AI2 -> 2.401943 | W2: {='VATtax et trade tax et ipc '!AK2:AK218} -> 3.0990709 | X2: ='VATtax et trade tax et ipc '!AM2 -> 2.4633253 | AA2: 0 | AB2: 1 | AC2: 38.77887
A3: Albania | B3: =Tx_croissance!AH3 -> 4.7096771 | C3: =IFERROR(LN(P3),"NA") -> 7.3052022 | D3: 28.234992 | E3: -0.51387055 | F3: -0.30570641 | G3: 76.962704 | H3: -0.07743383 | I3: 87.204486 | J3: 39.967874 | K3: 5.6691786 | L3: -0.6724434 | M3: 0.020878915 | N3: -0.53877781 | O3: 0.034698074 | P3: 1488.0209 | Q3: 16.430994 | R3: 19.034249 | S3: 13.1 | T3: 13.141789 | U3: 66.809868 | V3: ='VATtax et trade tax et ipc '!AI3 -> 13.416597 | W3: 0.91035615 | X3: ='VATtax et trade tax et ipc '!AM3 -> 3.7756395 | Y3: 13.600788 | Z3: 21.278513 | AA3: 0 | AB3: 1 | AC3: 9.4345675
A4: Algeria | B4: =Tx_croissance!AH4 -> 1.2472527 | C4: =IFERROR(LN(P4),"NA") -> 7.9593136 | D4: 30.722778 | E4: 1.694848 | F4: -0.57214574 | G4: 72.826667 | H4: -1.2189323 | I4: 107.48072 | J4: 22.097866 | K4: 5.4010473 | L4: -0.64930455 | M4: -0.96427201 | N4: -0.84774298 | O4: -0.97832619 | P4: 2862.1079 | Q4: NA | R4: #DIV/0! | S4: 7.6266667 | T4: #DIV/0! | U4: NA | V4: ='VATtax et trade tax et ipc '!AI4 -> NA | W4: NA | X4: ='VATtax et trade tax et ipc '!AM4 -> NA | Z4: 29.136944 | AA4: 0 | AB4: 1 | AC4: NA
A5: American Samoa | B5: =Tx_croissance!AH5 -> NA | C5: =IFERROR(LN(P5),"NA") -> NA | D5: NA | E5: -0.59425675 | F5: 0.45066375 | G5: NA | H5: 0.99981607 | I5: 107.93092 | J5: 86.952467 | K5: 38.056991 | L5: 0.88248917 | M5: 0.26575818 | N5: 1.1612325 | O5: 0.91652832 | P5: NA | Q5: NA | R5: #DIV/0! | S5: #DIV/0! | T5: #DIV/0! | U5: NA | V5: ='VATtax et trade tax et ipc '!AI5 -> NA | W5: NA | X5: ='VATtax et trade tax et ipc '!AM5 -> NA | AA5: 0 | AB5: 0 | AC5: NA
A6: Andorra | B6: =Tx_croissance!AH6 -> 1.2707207 | C6: =IFERROR(LN(P6),"NA") -> 10.241794 | D6: NA | E6: 0.95837133 | F6: 1.572452 | G6: NA | H6: 1.3621018 | I6: 89.527079 | J6: 89.524159 | K6: 13.653441 | L6: 1.252925 | M6: 1.3059024 | N6: 1.3283595 | O6: 1.3110088 | P6: 28051.403 | Q6: NA | R6: #DIV/0! | S6: #DIV/0! | T6: #DIV/0! | U6: NA | V6: ='VATtax et trade tax et ipc '!AI6 -> NA | W6: NA | X6: ='VATtax et trade tax et ipc '!AM6 -> NA | AA6: 0 | AB6: 0 | AC6: NA
A7: Angola | B7: =Tx_croissance!AH7 -> 1.3160424 | C7: =IFERROR(LN(P7),"NA") -> 7.4239911 | D7: 26.839838 | E7: 3.4720108 | F7: -1.0962019 | G7: 54.111889 | H7: -0.76937486 | I7: 110.11878 | J7: 90.954865 | K7: 49.593525 | L7: -1.2330975 | M7: -1.0589671 | N7: -1.2683666 | O7: -1.1383518 | P7: 1675.7081 | Q7: 16.951172 | R7: 75.134266 | S7: 23.92 | T7: 40.214544 | U7: NA | V7: ='VATtax et trade tax et ipc '!AI7 -> 1.1549995 | W7: 0.70915725 | X7: ='VATtax et trade tax et ipc '!AM7 -> 7.7522472 | AA7: 0 | AB7: 1 | AC7: 6.4242978
A8: Antigua and Barbuda | B8: =Tx_croissance!AH8 -> 0.90711749 | C8: =IFERROR(LN(P8),"NA") -> 9.516668 | D8: NA | E8: 1.1964416 | F8: 1.2284783 | G8: 76.391519 | H8: 0.86728527 | I8: 114.70298 | J8: 98.955017 | K8: 74.241269 | L8: 0.80119645 | M8: 0.54966119 | N8: 0.71992285 | O8: 0.55544067 | P8: 13584.273 | Q8: NA | R8: #DIV/0! | S8: 27.873333 | T8: #DIV/0! | U8: NA | V8: ='VATtax et trade tax et ipc '!AI8 -> NA | W8: NA | X8: ='VATtax et trade tax et ipc '!AM8 -> NA | AA8: 0 | AB8: 0 | AC8: NA
A9: Argentina | B9: =Tx_croissance!AH9 -> 0.97085591 | C9: =IFERROR(LN(P9),"NA") -> 9.2072688 | D9: 16.526854 | E9: 1.0467921 | F9: 0.309166 | G9: 75.272593 | H9: -0.062694981 | I9: 99.739047 | J9: 89.30783 | K9: 41.944904 | L9: -0.34692161 | M9: -0.52550969 | N9: -0.51334566 | O9: 0.40665429 | P9: 9969.3316 | Q9: 10.465761 | R9: 21.450258 | S9: 2.72 | T9: 13.771817 | U9: NA | V9: ='VATtax et trade tax et ipc '!AI9 -> 3.9050876 | W9: 1.5709463 | X9: ='VATtax et trade tax et ipc '!AM9 -> 1.3523403 | Y9: 8.0543577 | Z9: 17.937746 | AA9: 0 | AB9: 0 | AC9: 6.1704262
A10: Armenia | B10: =Tx_croissance!AH10 -> 6.5264997 | C10: =IFERROR(LN(P10),"NA") -> 6.8331314 | D10: 24.927534 | E10: -0.69069393 | F10: -0.07553162 | G10: 72.329667 | H10: -0.27584209 | I10: NA | J10: NA | K10: NA | L10: -0.55545039 | M10: 0.15242438 | N10: -0.35538289 | O10: -0.47553955 | P10: 928.0925 | Q10: 18.749481 | R10: 32.915449 | S10: 16.62 | T10: 27.466847 | U10: 57.836665 | V10: ='VATtax et trade tax et ipc '!AI10 -> 12.528264 | W10: 1.3716237 | X10: ='VATtax et trade tax et ipc '!AM10 -> 9.0651098 | Z10: 16.153955 | AA10: 0 | AB10: 1 | AC10: 5.3095739
A11: Aruba | B11: =Tx_croissance!AH11 -> 0.35870917 | C11: =IFERROR(LN(P11),"NA") -> 10.292076 | D11: NA | E11: 1.2643374 | F11: -0.22971242 | G11: 74.586444 | H11: 1.2768626 | I11: 115.11915 | J11: 113.40096 | K11: NA | L11: 1.1393865 | M11: 1.0875311 | N11: 1.1622112 | O11: 1.1683587 | P11: 29497.963 | Q11: NA | R11: #DIV/0! | S11: #DIV/0! | T11: #DIV/0! | U11: NA | V11: ='VATtax et trade tax et ipc '!AI11 -> NA | W11: NA | X11: ='VATtax et trade tax et ipc '!AM11 -> NA | AA11: 0 | AB11: 0 | AC11: NA
A12: Australia | B12: =Tx_croissance!AH12 -> 1.6403108 | C12: =IFERROR(LN(P12),"NA") -> 10.579234 | D12: 25.514464 | E12: 1.3528714 | F12: 1.1339919 | G12: 81.006775 | H12: 0.98132158 | I12: 102.78112 | J12: 146.69508 | K12: 101.18495 | L12: 1.8690129 | M12: 1.7265004 | N12: 1.7302952 | O12: 1.3990897 | P12: 39309.995 | Q12: 21.895615 | R12: 72.064757 | S12: 26.266667 | T12: 64.892736 | U12: 35.458215 | V12: ='VATtax et trade tax et ipc '!AI12 -> 5.4911305 | W12: 0.67024513 | X12: ='VATtax et trade tax et ipc '!AM12 -> 16.434395 | Y12: 21.159594 | Z12: 25.095292 | AA12: 0 | AB12: 0 | AC12: 2.8204189
A13: Austria | B13: =Tx_croissance!AH13 -> 1.205426 | C13: =IFERROR(LN(P13),"NA") -> 10.427935 | D13: 23.921077 | E13: 0.46585597 | F13: 1.6610913 | G13: 79.828726 | H13: 1.0967106 | I13: 101.698 | J13: 100.66312 | K13: 73.446607 | L13: 1.6486806 | M13: 1.4838394 | N13: 1.8280325 | O13: 1.3867748 | P13: 33790.485 | Q13: 22.430875 | R13: 46.996991 | S13: 16.86 | T13: 27.53463 | U13: 80.368534 | V13: ='VATtax et trade tax et ipc '!AI13 -> 11.745178 | W13: -0.0027464446 | X13: ='VATtax et trade tax et ipc '!AM13 -> 11.93604 | Y13: 24.600106 | Z13: 25.299058 | AA13: 0 | AB13: 0 | AC13: 0.0098863037
A14: Azerbaijan | B14: =Tx_croissance!AH14 -> 6.1970333 | C14: =IFERROR(LN(P14),"NA") -> 7.0053337 | D14: 26.805767 | E14: 1.0320249 | F14: 1.6619661 | G14: 68.094741 | H14: -0.74111291 | I14: 98.485199 | J14: 84.919172 | K14: 25.63076 | L14: -1.0847096 | M14: -0.47731127 | N14: -0.82028031 | O14: -1.3069318 | P14: 1102.4979 | Q14: 14.193999 | R14: 36.101595 | S14: 13.4 | T14: 15.683281 | U14: 11.25391 | V14: ='VATtax et trade tax et ipc '!AI14 -> 8.2392438 | W14: 1.4743464 | X14: ='VATtax et trade tax et ipc '!AM14 -> 6.0267988 | Y14: 17.954073 | Z14: 15.643453 | AA14: 0 | AB14: 1 | AC14: 7.5939685
A15: Bahamas, The | B15: =Tx_croissance!AH15 -> 0.2367812 | C15: =IFERROR(LN(P15),"NA") -> 10.254516 | D15: 26.505855 | E15: 1.1876735 | F15: -0.55437021 | G15: 72.391037 | H15: 0.94337777 | I15: 96.945866 | J15: 29.503661 | K15: 3.1290701 | L15: 1.2644203 | M15: 0.58671984 | N15: 0.75484677 | O15: 0.98894457 | P15: 28410.556 | Q15: 12.933436 | R15: #DIV/0! | S15: 0 | T15: #DIV/0! | U15: 42.184055 | V15: ='VATtax et trade tax et ipc '!AI15 -> 5.7376246 | W15: 5.172775 | X15: ='VATtax et trade tax et ipc '!AM15 -> NA | Y15: 17.346165 | Z15: 25.438612 | AA15: 0 | AB15: 0 | AC15: 35.734648
A16: Bahrain | B16: =Tx_croissance!AH16 -> 0.66403743 | C16: =IFERROR(LN(P16),"NA") -> 9.9234554 | D16: 23.467916 | E16: 3.2461176 | F16: 0.91198128 | G16: 77.508111 | H16: -0.45629006 | I16: 102.61714 | J16: 155.73887 | K16: 67.336749 | L16: 0.20715693 | M16: 0.68849758 | N16: 0.42452549 | O16: -1.0894483 | P16: 20403.371 | Q16: 4.8338218 | R16: 27.34312 | S16: 0 | T16: 4.3790231 | U16: 23.769771 | V16: ='VATtax et trade tax et ipc '!AI16 -> 0.31447793 | W16: 0.63554918 | X16: ='VATtax et trade tax et ipc '!AM16 -> 0.43292226 | Y16: 4.796763 | Z16: 17.327454 | AA16: 0 | AB16: 0 | AC16: 41.223081
A17: Bangladesh | B17: =Tx_croissance!AH17 -> 4.3885534 | C17: =IFERROR(LN(P17),"NA") -> 6.3273817 | D17: 26.658804 | E17: 1.4017432 | F17: 0.45139074 | G17: 67.719222 | H17: -1.1891145 | I17: 103.30039 | J17: 39.306518 | K17: 8.4604723 | L17: -1.0820966 | M17: -0.93982781 | N17: -0.82140678 | O17: -0.48791288 | P17: 559.68923 | Q17: 7.5968699 | R17: 25.449192 | S17: 31.071429 | T17: 20.232594 | U17: 31.510096 | V17: ='VATtax et trade tax et ipc '!AI17 -> 4.0092421 | W17: 1.8015978 | X17: ='VATtax et trade tax et ipc '!AM17 -> 2.5116353 | Z17: 19.119796 | AA17: 0 | AB17: 1 | AC17: 28.821819
A18: Barbados | B18: =Tx_croissance!AH18 -> 0.57238029 | C18: =IFERROR(LN(P18),"NA") -> 9.5623417 | D18: 16.778978 | E18: 0.26202587 | F18: -0.75506117 | G18: 75.431556 | H18: 1.0822522 | I18: 67.930978 | J18: 24.278902 | K18: 3.9475652 | L18: 1.4049004 | M18: 0.75509913 | N18: 0.98860834 | O18: 1.1252438 | P18: 14219.104 | Q18: 25.246765 | R18: 34.357319 | S18: 19.622222 | T18: 31.820108 | U18: 99.753458 | V18: ='VATtax et trade tax et ipc '!AI18 -> 13.164133 | W18: 2.5135495 | X18: ='VATtax et trade tax et ipc '!AM18 -> 9.2873308 | Z18: 11.661808 | AA18: 0 | AB18: 0 | AC18: 9.1156998
A19: Belarus | B19: =Tx_croissance!AH19 -> 4.507885 | C19: =IFERROR(LN(P19),"NA") -> 7.542472 | D19: 27.849921 | E19: -0.36706017 | F19: 1.1357789 | G19: 70.638432 | H19: 0.078517446 | I19: 105.78866 | J19: 55.475698 | K19: 12.775785 | L19: -0.43211972 | M19: -1.1852769 | N19: -1.0220175 | O19: -1.4641737 | P19: 1886.4877 | Q19: 17.44036 | R19: 11.051499 | S19: 15.88 | T19: 6.1935302 | U19: 21.037599 | V19: ='VATtax et trade tax et ipc '!AI19 -> 8.0357778 | W19: 3.1923354 | X19: ='VATtax et trade tax et ipc '!AM19 -> 0.85928337 | Y19: 19.887647 | Z19: 24.697907 | AA19: 0 | AB19: 0 | AC19: 9.603561
A20: Belgium | B20: =Tx_croissance!AH20 -> 1.2814957 | C20: =IFERROR(LN(P20),"NA") -> 10.352328 | D20: 22.601563 | E20: 0.5153448 | F20: -0.83133648 | G20: 79.565086 | H20: 0.7702138 | I20: 101.35388 | J20: 92.131931 | K20: 55.878957 | L20: 1.437862 | M20: 1.2696099 | N20: 1.3549161 | O20: 1.3580424 | P20: 31329.892 | Q20: 25.085864 | R20: 57.613329 | S20: 8.5 | T20: 35.425657 | U20: 106.0602 | V20: ='VATtax et trade tax et ipc '!AI20 -> 10.118285 | W20: NA | X20: ='VATtax et trade tax et ipc '!AM20 -> 13.953597 | Y20: 25.622419 | Z20: 21.231741 | AA20: 0 | AB20: 0 | AC20: NA
A21: Belize | B21: =Tx_croissance!AH21 -> 0.81824313 | C21: =IFERROR(LN(P21),"NA") -> 8.5109323 | D21: 17.747519 | E21: 2.5506879 | F21: 1.5396026 | G21: 71.090037 | H21: 0.21959279 | I21: 96.8926 | J21: 90.5701 | K21: 40.954326 | L21: -0.15975439 | M21: -0.28267077 | N21: -0.39967279 | O21: 0.65727731 | P21: 4968.7932 | Q21: 16.427327 | R21: 27.729823 | S21: 24.7 | T21: 23.391049 | U21: 59.624879 | V21: ='VATtax et trade tax et ipc '!AI21 -> 6.3035175 | W21: 4.6893769 | X21: ='VATtax et trade tax et ipc '!AM21 -> 4.6216683 | Y21: 14.243196 | Z21: 19.561072 | AA21: 0 | AB21: 0 | AC21: 43.637766
A22: Benin | B22: =Tx_croissance!AH22 -> 1.6630842 | C22: =IFERROR(LN(P22),"NA") -> 6.6900349 | D22: 19.800557 | E22: 2.9029332 | F22: -0.2037761 | G22: 57.924815 | H22: 0.25150338 | I22: NA | J22: 83.060659 | K22: 14.33432 | L22: -0.54896374 | M22: -0.45623376 | N22: -0.50650971 | O22: 0.18884809 | P22: 804.35033 | Q22: 12.269847 | R22: #DIV/0! | S22: 15.426667 | T22: #DIV/0! | U22: NA | V22: ='VATtax et trade tax et ipc '!AI22 -> NA | W22: NA | X22: ='VATtax et trade tax et ipc '!AM22 -> NA | Z22: 17.564867 | AA22: 0 | AB22: 1 | AC22: NA
A23: Bermuda | B23: =Tx_croissance!AH23 -> 0.64051094 | C23: =IFERROR(LN(P23),"NA") -> 11.402198 | D23: 12.636803 | E23: 0.24499 | F23: -0.50903461 | G23: 79.759667 | H23: 0.8931456 | I23: 93.126175 | J23: 84.573198 | K23: 35.584385 | L23: 1.2607275 | M23: 1.2075273 | N23: 0.90820859 | O23: 1.0565776 | P23: 89518.278 | Q23: NA | R23: #DIV/0! | S23: #DIV/0! | T23: #DIV/0! | U23: NA | V23: ='VATtax et trade tax et ipc '!AI23 -> NA | W23: NA | X23: ='VATtax et trade tax et ipc '!AM23 -> NA | AA23: 0 | AB23: 0 | AC23: NA
A24: Bhutan | B24: =Tx_croissance!AH24 -> NA | C24: =IFERROR(LN(P24),"NA") -> 6.8505578 | D24: 50.534339 | E24: 1.4506695 | F24: 1.1320169 | G24: 66.759296 | H24: 0.89031048 | I24: 100.13653 | J24: 98.674237 | K24: 71.284453 | L24: 1.0714155 | M24: -0.63584256 | N24: 0.33951693 | O24: -0.47107942 | P24: 944.40756 | Q24: 9.2555309 | R24: 53.832345 | S24: 33.42 | T24: 18.025831 | U24: 69.061865 | V24: ='VATtax et trade tax et ipc '!AI24 -> 4.9238723 | W24: 0.79130598 | X24: ='VATtax et trade tax et ipc '!AM24 -> 6.2481379 | Y24: 6.898255 | Z24: 42.317708 | AA24: 0 | AB24: 1 | AC24: 3.2686868
A25: Bolivia | B25: =Tx_croissance!AH25 -> 1.9385795 | C25: =IFERROR(LN(P25),"NA") -> 7.5319022 | D25: 17.404931 | E25: 1.6535913 | F25: 0.4656296 | G25: 64.634926 | H25: -0.45960037 | I25: 115.03735 | J25: 78.156679 | K25: 21.133021 | L25: -0.68099136 | M25: -0.71039483 | N25: -0.90665773 | O25: -0.014136566 | P25: 1866.6529 | Q25: 11.206035 | R25: 11.104858 | S25: 0 | T25: 6.683974 | U25: 54.801788 | V25: ='VATtax et trade tax et ipc '!AI25 -> 4.4863966 | W25: 0.37027745 | X25: ='VATtax et trade tax et ipc '!AM25 -> 0.70856584 | Y25: 9.7223295 | Z25: 15.533527 | AA25: 0 | AB25: 1 | AC25: 7.1759694
A26: Bosnia and Herzegovina | B26: =Tx_croissance!AH26 -> 7.9975228 | C26: =IFERROR(LN(P26),"NA") -> 6.6651979 | D26: 24.760237 | E26: -0.54094737 | F26: -0.51303612 | G26: 75.672074 | H26: -0.45036886 | I26: 104.79967 | J26: 88.698727 | K26: 33.22389 | L26: -0.42206778 | M26: -0.2956734 | N26: -0.36336778 | O26: -0.075485842 | P26: 784.6187 | Q26: 19.921778 | R26: 12.128134 | S26: 11.166667 | T26: 6.2870854 | U26: 47.350149 | V26: ='VATtax et trade tax et ipc '!AI26 -> 21.712007 | W26: 0.54791374 | X26: ='VATtax et trade tax et ipc '!AM26 -> 3.3420054 | Z26: 12.268473 | AA26: 0 | AB26: 1 | AC26: 3.4175339
A27: Botswana | B27: =Tx_croissance!AH27 -> 1.6572815 | C27: =IFERROR(LN(P27),"NA") -> 8.3597135 | D27: 26.430882 | E27: 1.9973979 | F27: -0.78058553 | G27: 57.751111 | H27: 1.0226195 | I27: NA | J27: 76.921761 | K27: NA | L27: 0.85730213 | M27: 0.66657609 | N27: 0.52307551 | O27: 0.53779007 | P27: 4271.4709 | Q27: 24.13014 | R27: 41.685927 | S27: 19.213333 | T27: 26.27628 | U27: 15.464161 | V27: ='VATtax et trade tax et ipc '!AI27 -> 5.947078 | W27: 11.65696 | X27: ='VATtax et trade tax et ipc '!AM27 -> 12.011415 | Y27: 16.765796 | Z27: 26.977627 | AA27: 0 | AB27: 0 | AC27: 39.280682
A28: Brazil | B28: =Tx_croissance!AH28 -> 1.1274772 | C28: =IFERROR(LN(P28),"NA") -> 8.7833225 | D28: 18.155147 | E28: 1.0386144 | F28: 0.4347906 | G28: 72.110111 | H28: -0.22298419 | I28: 114.16318 | J28: 102.71184 | K28: 41.292828 | L28: -0.18316958 | M28: 0.037600805 | N28: -0.22986735 | O28: 0.41737558 | P28: 6524.5189 | Q28: 13.975226 | R28: 51.190242 | S28: 22.342857 | T28: 25.028306 | U28: 74.247132 | V28: ='VATtax et trade tax et ipc '!AI28 -> 9.4143723 | W28: 0.99148007 | X28: ='VATtax et trade tax et ipc '!AM28 -> 11.983306 | Z28: 20.286298 | AA28: 0 | AB28: 0 | AC28: 4.3004342
A29: British Virgin Islands | B29: =Tx_croissance!AH29 -> NA | C29: =IFERROR(LN(P29),"NA") -> NA | D29: NA | E29: 2.1274138 | F29: -0.220761 | G29: 74.936481 | H29: NA | I29: 99.755564 | J29: 107.51422 | K29: 55.078339 | L29: NA | M29: NA | N29: NA | O29: NA | P29: NA | Q29: NA | R29: #DIV/0! | S29: #DIV/0! | T29: #DIV/0! | U29: NA | V29: ='VATtax et trade tax et ipc '!AI29 -> NA | W29: NA | X29: ='VATtax et trade tax et ipc '!AM29 -> NA | AA29: 0 | AB29: 0 | AC29: NA
A30: Brunei Darussalam | B30: =Tx_croissance!AH30 -> -0.75369466 | C30: =IFERROR(LN(P30),"NA") -> 10.477734 | D30: 26.477194 | E30: 1.5374863 | F30: 0.96167488 | G30: 74.443963 | H30: 1.1823548 | I30: 102.4183 | J30: 87.681696 | K30: 20.312394 | L30: 0.60866668 | M30: 0.95820407 | N30: 0.58958852 | O30: -0.79594648 | P30: 35515.843 | Q30: NA | R30: #DIV/0! | S30: 11.507143 | T30: #DIV/0! | U30: NA | V30: ='VATtax et trade tax et ipc '!AI30 -> NA | W30: NA | X30: ='VATtax et trade tax et ipc '!AM30 -> NA | Z30: 36.661699 | AA30: 0 | AB30: 0 | AC30: NA
A31: Bulgaria | B31: =Tx_croissance!AH31 -> 3.2515765 | C31: =IFERROR(LN(P31),"NA") -> 8.3004406 | D31: 19.762658 | E31: -0.95353456 | F31: -0.021032884 | G31: 72.952647 | H31: 0.28493553 | I31: 94.839586 | J31: 62.908112 | K31: 10.062492 | L31: -0.21097233 | M31: 0.52859139 | N31: -0.12190507 | O31: 0.45300526 | P31: 4025.6458 | Q31: 19.401704 | R31: 28.876291 | S31: 5.1933333 | T31: 15.908964 | U31: 35.144067 | V31: ='VATtax et trade tax et ipc '!AI31 -> 13.424183 | W31: 0.18066 | X31: ='VATtax et trade tax et ipc '!AM31 -> 5.219091 | Y31: 11.156664 | Z31: 16.668561 | AA31: 0 | AB31: 0 | AC31: 2.9037661
A32: Burkina Faso | B32: =Tx_croissance!AH32 -> 2.7088643 | C32: =IFERROR(LN(P32),"NA") -> 5.8748969 | D32: 18.681561 | E32: 2.891211 | F32: -0.71028564 | G32: 54.921556 | H32: -0.52705767 | I32: 102.91694 | J32: 73.603632 | K32: 15.048078 | L32: -0.19425634 | M32: -0.32293118 | N32: -0.51396338 | O32: -0.27706748 | P32: 355.98794 | Q32: 12.702878 | R32: 26.265196 | S32: 16.62 | T32: 18.570685 | U32: 55.43971 | V32: ='VATtax et trade tax et ipc '!AI32 -> 8.5054231 | W32: 2.460246 | X32: ='VATtax et trade tax et ipc '!AM32 -> 4.3564671 | Z32: 22.479807 | AA32: 0 | AB32: 1 | AC32: 15.793083
A33: Burundi | B33: =Tx_croissance!AH33 -> -1.1070687 | C33: =IFERROR(LN(P33),"NA") -> 5.8696251 | D33: 11.193935 | E33: 2.9860086 | F33: -1.3055631 | G33: 54.540593 | H33: -1.7116444 | I33: 72.826495 | J33: 13.562921 | K33: 2.1412545 | L33: -1.1802308 | M33: -1.0978512 | N33: -1.2744365 | O33: -1.1844699 | P33: 354.11618 | Q33: NA | R33: 24.565344 | S33: 25.62 | T33: 17.219889 | U33: 144.22053 | V33: ='VATtax et trade tax et ipc '!AI33 -> 0.82351818 | W33: 0.44399098 | X33: ='VATtax et trade tax et ipc '!AM33 -> 0.41593262 | Y33: 16.678207 | Z33: 6.4429994 | AA33: 0 | AB33: 1 | AC33: 18.121549
A34: Cabo Verde | B34: =Tx_croissance!AH34 -> 3.8240248 | C34: =IFERROR(LN(P34),"NA") -> 7.1457307 | D34: NA | E34: 1.392329 | F34: 0.015781369 | G34: 72.108037 | H34: 0.86119937 | I34: 99.134542 | J34: 106.40359 | K34: 68.096208 | L34: 0.85061409 | M34: -0.14638214 | N34: 0.49301043 | O34: 0.86588946 | P34: 1268.678 | Q34: 17.988903 | R34: 30.578555 | S34: 19.373333 | T34: 18.595747 | U34: NA | V34: ='VATtax et trade tax et ipc '!AI34 -> 10.288915 | W34: 4.1933458 | X34: ='VATtax et trade tax et ipc '!AM34 -> 6.3904353 | AA34: 0 | AB34: 1 | AC34: 19.578392
A35: Cambodia | B35: =Tx_croissance!AH35 -> 5.1987922 | C35: =IFERROR(LN(P35),"NA") -> 5.9373314 | D35: 18.689547 | E35: 1.6256615 | F35: -0.78932999 | G35: 64.998222 | H35: -0.32878124 | I35: 102.53375 | J35: 98.211111 | K35: 50.570209 | L35: -1.1679486 | M35: -0.4676546 | N35: -1.0834278 | O35: -1.0185148 | P35: 378.92238 | Q35: 12.198874 | R35: 19.10624 | S35: 19.32 | T35: 13.93106 | U35: NA | V35: ='VATtax et trade tax et ipc '!AI35 -> 9.8419962 | W35: 2.995123 | X35: ='VATtax et trade tax et ipc '!AM35 -> 3.9723906 | Z35: 13.916833 | AA35: 0 | AB35: 1 | AC35: 20.012259
A36: Cameroon | B36: =Tx_croissance!AH36 -> 1.1824101 | C36: =IFERROR(LN(P36),"NA") -> 6.956266 | D36: 18.571178 | E36: 2.771044 | F36: -0.88050299 | G36: 56.344259 | H36: -0.81236008 | I36: NA | J36: NA | K36: NA | L36: -1.1602667 | M36: -0.8756812 | N36: -1.1248985 | O36: -1.0582847 | P36: 1049.7067 | Q36: 10.269042 | R36: 29.234389 | S36: 31.766667 | T36: 22.38712 | U36: 90.182967 | V36: ='VATtax et trade tax et ipc '!AI36 -> 6.8490888 | W36: 2.322554 | X36: ='VATtax et trade tax et ipc '!AM36 -> 4.1975948 | Y36: 7.183669 | Z36: 17.333571 | AA36: 0 | AB36: 1 | AC36: 17.959751
A37: Canada | B37: =Tx_croissance!AH37 -> 1.1936863 | C37: =IFERROR(LN(P37),"NA") -> 10.392443 | D37: 22.067825 | E37: 1.0515855 | F37: 1.7686003 | G37: 80.547309 | H37: 1.050072 | I37: 101.98573 | J37: 94.32557 | K37: 61.490332 | L37: 1.8909337 | M37: 1.6459304 | N37: 1.7256276 | O37: 1.4662967 | P37: 32612.232 | Q37: 13.205866 | R37: 76.329888 | S37: 10.906667 | T37: 53.395992 | U37: 57.577369 | V37: ='VATtax et trade tax et ipc '!AI37 -> 2.7428267 | W37: 0.24116831 | X37: ='VATtax et trade tax et ipc '!AM37 -> 9.9209642 | Y37: 13.287062 | Z37: 18.3473 | AA37: 0 | AB37: 0 | AC37: NA
A38: Cayman Islands | B38: =Tx_croissance!AH38 -> NA | C38: =IFERROR(LN(P38),"NA") -> NA | D38: NA | E38: 2.7944841 | F38: 1.3340247 | G38: 82.190244 | H38: 1.116959 | I38: 103.89109 | J38: 77.333903 | K38: 29.060357 | L38: 0.9968462 | M38: 1.1143373 | N38: 0.97377473 | O38: 0.79565808 | P38: NA | Q38: NA | R38: #DIV/0! | S38: #DIV/0! | T38: #DIV/0! | U38: NA | V38: ='VATtax et trade tax et ipc '!AI38 -> NA | W38: NA | X38: ='VATtax et trade tax et ipc '!AM38 -> NA | AA38: 0 | AB38: 0 | AC38: NA
A39: Central African Republic | B39: =Tx_croissance!AH39 -> -0.99971073 | C39: =IFERROR(LN(P39),"NA") -> 6.1703299 | D39: 12.95163 | E39: 1.9988948 | F39: -1.5470561 | G39: 49.143667 | H39: -1.8363351 | I39: 78.425447 | J39: 46.217832 | K39: 7.670532 | L39: -1.1691322 | M39: -1.2455818 | N39: -1.5203608 | O39: -1.1112256 | P39: 478.34389 | Q39: 7.4168613 | R39: 22.577926 | S39: 0 | T39: 11.379809 | U39: NA | V39: ='VATtax et trade tax et ipc '!AI39 -> 5.1847997 | W39: 2.7669079 | X39: ='VATtax et trade tax et ipc '!AM39 -> 2.3348734 | Z39: 13.053912 | AA39: 0 | AB39: 1 | AC39: 25.002107
A40: Chad | B40: =Tx_croissance!AH40 -> 1.4518322 | C40: =IFERROR(LN(P40),"NA") -> 5.9914633 | D40: 25.112545 | E40: 3.5316887 | F40: -1.3283807 | G40: 49.56537 | H40: -1.4087013 | I40: 102.10665 | J40: 39.452959 | K40: 9.6269121 | L40: -1.4089354 | M40: -1.1191018 | N40: -1.3720946 | O40: -1.3026839 | P40: 399.99949 | Q40: NA | R40: #DIV/0! | S40: 31.3 | T40: #DIV/0! | U40: NA | V40: ='VATtax et trade tax et ipc '!AI40 -> NA | W40: NA | X40: ='VATtax et trade tax et ipc '!AM40 -> NA | Z40: 14.357197 | AA40: 0 | AB40: 1 | AC40: NA
...

Sheet VATtax et trade tax et ipc 
A1: Series Name | B1: Series Code | C1: Country Name | D1: Country Code | E1: 1995 [YR1995] | F1: 1996 [YR1996] | G1: 1997 [YR1997] | H1: 1998 [YR1998] | I1: 1999 [YR1999] | J1: 2000 [YR2000] | K1: 2001 [YR2001] | L1: 2002 [YR2002] | M1: 2003 [YR2003] | N1: 2004 [YR2004] | O1: 2005 [YR2005] | P1: 2006 [YR2006] | Q1: 2007 [YR2007] | R1: 2008 [YR2008] | S1: 2009 [YR2009] | T1: 2010 [YR2010] | U1: 2011 [YR2011] | V1: 2012 [YR2012] | W1: 2013 [YR2013] | X1: 2014 [YR2014] | Y1: 2015 [YR2015] | Z1: 2016 [YR2016] | AA1: 2017 [YR2017] | AB1: 2018 [YR2018] | AC1: 2019 [YR2019] | AD1: 2020 [YR2020] | AE1: 2021 [YR2021] | AF1: 2022 [YR2022] | AG1: moyenne | AI1: VAT(lcu) / Gdp (lcu) = Vat/gdp | AK1: trade_tx_gdp = taxe sur le commerce international (%GDP) | AM1: incprofitcap_tx = tax on income profit and capital gain LCU / GDP LCU
A2: Taxes on goods and services (current LCU) | B2: GC.TAX.GSRV.CN | C2: Afghanistan | D2: AFG | E2: .. | F2: .. | G2: .. | H2: .. | I2: .. | J2: .. | K2: .. | L2: .. | M2: .. | N2: .. | O2: .. | P2: 5.9529439e+09 | Q2: 6.7020366e+09 | R2: 8.0706949e+09 | S2: 1.3497092e+10 | T2: 1.8435006e+10 | U2: 2.0918999e+10 | V2: 2.1452208e+10 | W2: 19386490829 | X2: 1.7309901e+10 | Y2: 1.7608166e+10 | Z2: 4.4737123e+10 | AA2: 5.3188617e+10 | AB2: .. | AC2: .. | AD2: .. | AE2: .. | AF2: .. | AG2: =IFERROR(AVERAGE(E2:AF2),"NA") -> 2.060494e+10 | AI2: =IFERROR(AG2*100/AG222,"NA") -> 2.401943 | AK2: =IFERROR(AG443*100/AG222,"NA") -> 3.0990709 | AM2: =IFERROR(AG664*100/AG222,"NA") -> 2.4633253
A3: Taxes on goods and services (current LCU) | B3: GC.TAX.GSRV.CN | C3: Albania | D3: ALB | E3: 18850000000 | F3: 15948958000 | G3: 18926363000 | H3: 35385497000 | I3: .. | J3: .. | K3: .. | L3: 64835600000 | M3: 76255180000 | N3: 89353960000 | O3: .. | P3: .. | Q3: .. | R3: .. | S3: .. | T3: .. | U3: 175055100000 | V3: 173505580000 | W3: 166375460000 | X3: 195997780000 | Y3: 200012910000 | Z3: 208378160000 | AA3: 218755890000 | AB3: 226077000000 | AC3: 220257210000 | AD3: 208303130000 | AE3: 251058420000 | AF3: .. | AG3: =IFERROR(AVERAGE(E3:AF3),"NA") -> 1.4240734e+11 | AI3: =IFERROR(AG3*100/AG223,"NA") -> 13.416597 | AK3: =IFERROR(AG444*100/AG223,"NA") -> 0.91035615 | AM3: =IFERROR(AG665*100/AG223,"NA") -> 3.7756395
A4: Taxes on goods and services (current LCU) | B4: GC.TAX.GSRV.CN | C4: Algeria | D4: DZA | E4: .. | F4: .. | G4: .. | H4: .. | I4: .. | J4: .. | K4: .. | L4: .. | M4: .. | N4: .. | O4: .. | P4: .. | Q4: .. | R4: .. | S4: .. | T4: .. | U4: .. | V4: .. | W4: .. | X4: .. | Y4: .. | Z4: .. | AA4: .. | AB4: .. | AC4: .. | AD4: .. | AE4: .. | AF4: .. | AG4: =IFERROR(AVERAGE(E4:AF4),"NA") -> NA | AI4: =IFERROR(AG4*100/AG224,"NA") -> NA | AK4: =IFERROR(AG445*100/AG224,"NA") -> NA | AM4: =IFERROR(AG666*100/AG224,"NA") -> NA
A5: Taxes on goods and services (current LCU) | B5: GC.TAX.GSRV.CN | C5: American Samoa | D5: ASM | E5: .. | F5: .. | G5: .. | H5: .. | I5: .. | J5: .. | K5: .. | L5: .. | M5: .. | N5: .. | O5: .. | P5: .. | Q5: .. | R5: .. | S5: .. | T5: .. | U5: .. | V5: .. | W5: .. | X5: .. | Y5: .. | Z5: .. | AA5: .. | AB5: .. | AC5: .. | AD5: .. | AE5: .. | AF5: .. | AG5: =IFERROR(AVERAGE(E5:AF5),"NA") -> NA | AI5: =IFERROR(AG5*100/AG225,"NA") -> NA | AK5: =IFERROR(AG446*100/AG225,"NA") -> NA | AM5: =IFERROR(AG667*100/AG225,"NA") -> NA
A6: Taxes on goods and services (current LCU) | B6: GC.TAX.GSRV.CN | C6: Andorra | D6: AND | E6: .. | F6: .. | G6: .. | H6: .. | I6: .. | J6: .. | K6: .. | L6: .. | M6: .. | N6: .. | O6: .. | P6: .. | Q6: .. | R6: .. | S6: .. | T6: .. | U6: .. | V6: .. | W6: .. | X6: .. | Y6: .. | Z6: .. | AA6: .. | AB6: .. | AC6: .. | AD6: .. | AE6: .. | AF6: .. | AG6: =IFERROR(AVERAGE(E6:AF6),"NA") -> NA | AI6: =IFERROR(AG6*100/AG226,"NA") -> NA | AK6: =IFERROR(AG447*100/AG226,"NA") -> NA | AM6: =IFERROR(AG668*100/AG226,"NA") -> NA
A7: Taxes on goods and services (current LCU) | B7: GC.TAX.GSRV.CN | C7: Angola | D7: AGO | E7: .. | F7: .. | G7: .. | H7: .. | I7: 3.2635839e+08 | J7: 1495978615 | K7: 17300349784 | L7: 12670999806 | M7: 30463029879 | N7: 41894421449 | O7: 51456380174 | P7: 68937892658 | Q7: 92906282322 | R7: 137367000000 | S7: 149494000000 | T7: 162085000000 | U7: 170041000000 | V7: 165995000000 | W7: 202397000000 | X7: 228895697526 | Y7: 176561786757 | Z7: 209778948579 | AA7: 246820082710 | AB7: 273026007438 | AC7: 3.5989858e+11 | AD7: .. | AE7: .. | AF7: .. | AG7: =IFERROR(AVERAGE(E7:AF7),"NA") -> 1.3332437e+11 | AI7: =IFERROR(AG7*100/AG227,"NA") -> 1.1549995 | AK7: =IFERROR(AG448*100/AG227,"NA") -> 0.70915725 | AM7: =IFERROR(AG669*100/AG227,"NA") -> 7.7522472
A8: Taxes on goods and services (current LCU) | B8: GC.TAX.GSRV.CN | C8: Antigua and Barbuda | D8: ATG | E8: .. | F8: .. | G8: .. | H8: .. | I8: .. | J8: .. | K8: .. | L8: .. | M8: .. | N8: .. | O8: .. | P8: .. | Q8: .. | R8: .. | S8: .. | T8: .. | U8: .. | V8: .. | W8: .. | X8: .. | Y8: .. | Z8: .. | AA8: .. | AB8: .. | AC8: .. | AD8: .. | AE8: .. | AF8: .. | AG8: =IFERROR(AVERAGE(E8:AF8),"NA") -> NA | AI8: =IFERROR(AG8*100/AG228,"NA") -> NA | AK8: =IFERROR(AG449*100/AG228,"NA") -> NA | AM8: =IFERROR(AG670*100/AG228,"NA") -> NA
A9: Taxes on goods and services (current LCU) | B9: GC.TAX.GSRV.CN | C9: Argentina | D9: ARG | E9: 13203700000 | F9: 13931400000 | G9: 16227200000 | H9: 17185200000 | I9: 16728900000 | J9: 17674300000 | K9: 16224000000 | L9: 16481800000 | M9: 2.2164551e+10 | N9: 3.0264212e+10 | O9: 36184400000 | P9: 44376700000 | Q9: 54722400000 | R9: 69210800000 | S9: 76968800000 | T9: 101267600000 | U9: 130577600000 | V9: 165330200000 | W9: 210696000000 | X9: 282293400000 | Y9: 369418100000 | Z9: 478910200000 | AA9: 624789300000 | AB9: 871333500000 | AC9: 1.2081107e+12 | AD9: 1.5030353e+12 | AE9: 2.6026779e+12 | AF9: .. | AG9: =IFERROR(AVERAGE(E9:AF9),"NA") -> 3.3370326e+11 | AI9: =IFERROR(AG9*100/AG229,"NA") -> 3.9050876 | AK9: =IFERROR(AG450*100/AG229,"NA") -> 1.5709463 | AM9: =IFERROR(AG671*100/AG229,"NA") -> 1.3523403
A10: Taxes on goods and services (current LCU) | B10: GC.TAX.GSRV.CN | C10: Armenia | D10: ARM | E10: .. | F10: .. | G10: .. | H10: .. | I10: .. | J10: .. | K10: .. | L10: .. | M10: .. | N10: 113048383600 | O10: 1.4457726e+11 | P10: 163233826600 | Q10: 2.8672424e+11 | R10: 361177594616 | S10: 293121813614 | T10: 346424420350 | U10: 364465369127 | V10: 415937000000 | W10: 453982449672 | X10: 532789401680 | Y10: 472922401444 | Z10: 450833122380 | AA10: 488914300373 | AB10: 547181002880 | AC10: 757077840956 | AD10: 719724611359 | AE10: 867184153472 | AF10: .. | AG10: =IFERROR(AVERAGE(E10:AF10),"NA") -> 4.321844e+11 | AI10: =IFERROR(AG10*100/AG230,"NA") -> 12.528264 | AK10: =IFERROR(AG451*100/AG230,"NA") -> 1.3716237 | AM10: =IFERROR(AG672*100/AG230,"NA") -> 9.0651098
A11: Taxes on goods and services (current LCU) | B11: GC.TAX.GSRV.CN | C11: Aruba | D11: ABW | E11: .. | F11: .. | G11: .. | H11: .. | I11: .. | J11: .. | K11: .. | L11: .. | M11: .. | N11: .. | O11: .. | P11: .. | Q11: .. | R11: .. | S11: .. | T11: .. | U11: .. | V11: .. | W11: .. | X11: .. | Y11: .. | Z11: .. | AA11: .. | AB11: .. | AC11: .. | AD11: .. | AE11: .. | AF11: .. | AG11: =IFERROR(AVERAGE(E11:AF11),"NA") -> NA | AI11: =IFERROR(AG11*100/AG231,"NA") -> NA | AK11: =IFERROR(AG452*100/AG231,"NA") -> NA | AM11: =IFERROR(AG673*100/AG231,"NA") -> NA
A12: Taxes on goods and services (current LCU) | B12: GC.TAX.GSRV.CN | C12: Australia | D12: AUS | E12: 24648000000 | F12: 26882000000 | G12: 27613000000 | H12: 28752000000 | I12: 30132000000 | J12: 30736000000 | K12: 46516000000 | L12: 50037000000 | M12: 55207000000 | N12: 58176000000 | O12: 60523000000 | P12: 63722000000 | Q12: 66728000000 | R12: 70880000000 | S12: 70121000000 | T12: 74182000000 | U12: 77407000000 | V12: 78152000000 | W12: 86713000000 | X12: 91660000000 | Y12: 84991000000 | Z12: 89412000000 | AA12: 92606000000 | AB12: 98174000000 | AC12: 100093000000 | AD12: 98478000000 | AE12: 109351000000 | AF12: 110605000000 | AG12: =IFERROR(AVERAGE(E12:AF12),"NA") -> 6.7946321e+10 | AI12: =IFERROR(AG12*100/AG232,"NA") -> 5.4911305 | AK12: =IFERROR(AG453*100/AG232,"NA") -> 0.67024513 | AM12: =IFERROR(AG674*100/AG232,"NA") -> 16.434395
A13: Taxes on goods and services (current LCU) | B13: GC.TAX.GSRV.CN | C13: Austria | D13: AUT | E13: 20702610000 | F13: 22196210000 | G13: 23388870000 | H13: 24271110000 | I13: 25476350000 | J13: 26328330000 | K13: 27440420000 | L13: 28532860000 | M13: 28814700000 | N13: 29955780000 | O13: 30799860000 | P13: 31403050000 | Q13: 32944000000 | R13: 34114870000 | S13: 34362710000 | T13: 35246410000 | U13: 37160460000 | V13: 38741900000 | W13: 39041190000 | X13: 39843080000 | Y13: 41215020000 | Z13: 42686270000 | AA13: 44022710000 | AB13: 45211970000 | AC13: 46718660000 | AD13: 43670950000 | AE13: 47573970000 | AF13: .. | AG13: =IFERROR(AVERAGE(E13:AF13),"NA") -> 3.4143123e+10 | AI13: =IFERROR(AG13*100/AG233,"NA") -> 11.745178 | AK13: =IFERROR(AG454*100/AG233,"NA") -> -0.0027464446 | AM13: =IFERROR(AG675*100/AG233,"NA") -> 11.93604
A14: Taxes on goods and services (current LCU) | B14: GC.TAX.GSRV.CN | C14: Azerbaijan | D14: AZE | E14: 130276600 | F14: 105032200 | G14: 193523200 | H14: 234531400 | I14: 264754200 | J14: .. | K14: .. | L14: .. | M14: .. | N14: .. | O14: .. | P14: .. | Q14: .. | R14: 2502800000 | S14: 2593000000 | T14: 2695600000 | U14: 2865100000 | V14: 3080200000 | W14: 3493800000 | X14: 4145800000 | Y14: 4404200000 | Z14: 4727000000 | AA14: 4808400000 | AB14: 5600004000 | AC14: 6541000000 | AD14: 6130300000 | AE14: 6739100000 | AF14: .. | AG14: =IFERROR(AVERAGE(E14:AF14),"NA") -> 3.2239169e+09 | AI14: =IFERROR(AG14*100/AG234,"NA") -> 8.2392438 | AK14: =IFERROR(AG455*100/AG234,"NA") -> 1.4743464 | AM14: =IFERROR(AG676*100/AG234,"NA") -> 6.0267988
A15: Taxes on goods and services (current LCU) | B15: GC.TAX.GSRV.CN | C15: Bahamas, The | D15: BHS | E15: 57800000 | F15: 35900000 | G15: 40911000 | H15: 50328000 | I15: 46930000 | J15: 119100000 | K15: 94000000 | L15: 102100000 | M15: 86300000 | N15: 117130000 | O15: 180285000 | P15: 334525000 | Q15: 388734000 | R15: 158400000 | S15: 373774000 | T15: 5.1574553e+08 | U15: 6.8342112e+08 | V15: 6.6521177e+08 | W15: 5.6438677e+08 | X15: 6.2878554e+08 | Y15: 9.0168065e+08 | Z15: 1.1545712e+09 | AA15: 1.2819658e+09 | AB15: 1275736000 | AC15: 1634363000 | AD15: 1346816646 | AE15: 1166624454 | AF15: 1488588337 | AG15: =IFERROR(AVERAGE(E15:AF15),"NA") -> 5.5336121e+08 | AI15: =IFERROR(AG15*100/AG235,"NA") -> 5.7376246 | AK15: =IFERROR(AG456*100/AG235,"NA") -> 5.172775 | AM15: =IFERROR(AG677*100/AG235,"NA") -> NA
A16: Taxes on goods and services (current LCU) | B16: GC.TAX.GSRV.CN | C16: Bahrain | D16: BHR | E16: 30200000 | F16: 28400000 | G16: 23800000 | H16: 22300000 | I16: 23100000 | J16: 25300000 | K16: 24300000 | L16: 26200000 | M16: 30700000 | N16: 32800000 | O16: .. | P16: .. | Q16: .. | R16: .. | S16: .. | T16: .. | U16: .. | V16: .. | W16: .. | X16: .. | Y16: .. | Z16: .. | AA16: .. | AB16: .. | AC16: .. | AD16: .. | AE16: .. | AF16: .. | AG16: =IFERROR(AVERAGE(E16:AF16),"NA") -> 26710000 | AI16: =IFERROR(AG16*100/AG236,"NA") -> 0.31447793 | AK16: =IFERROR(AG457*100/AG236,"NA") -> 0.63554918 | AM16: =IFERROR(AG678*100/AG236,"NA") -> 0.43292226
A17: Taxes on goods and services (current LCU) | B17: GC.TAX.GSRV.CN | C17: Bangladesh | D17: BGD | E17: .. | F17: .. | G17: .. | H17: .. | I17: .. | J17: .. | K17: 66568780000 | L17: 75228380000 | M17: 108949240000 | N17: 100539870000 | O17: 109990725000 | P17: 125517335000 | Q17: 140969068000 | R17: 171902957000 | S17: 200555946000 | T17: 240716688000 | U17: 304282400000 | V17: 352579400000 | W17: 402282200000 | X17: 428603900000 | Y17: 474400070000 | Z17: 577640000000 | AA17: 928708500000 | AB17: 1151751000000 | AC17: 1284988059000 | AD17: 1184613000000 | AE17: 1.4652468e+12 | AF17: .. | AG17: =IFERROR(AVERAGE(E17:AF17),"NA") -> 4.7123973e+11 | AI17: =IFERROR(AG17*100/AG237,"NA") -> 4.0092421 | AK17: =IFERROR(AG458*100/AG237,"NA") -> 1.8015978 | AM17: =IFERROR(AG679*100/AG237,"NA") -> 2.5116353
A18: Taxes on goods and services (current LCU) | B18: GC.TAX.GSRV.CN | C18: Barbados | D18: BRB | E18: .. | F18: .. | G18: .. | H18: .. | I18: .. | J18: .. | K18: .. | L18: .. | M18: 744568000 | N18: 878600000 | O18: 980641000 | P18: 9.8838044e+08 | Q18: 1090205310 | R18: 1100267475 | S18: 1002793628 | T18: 1077151137 | U18: 1284253544 | V18: 1144666163 | W18: 1151577522 | X18: 1063462232 | Y18: 1226930233 | Z18: 1317590062 | AA18: .. | AB18: .. | AC18: .. | AD18: .. | AE18: .. | AF18: .. | AG18: =IFERROR(AVERAGE(E18:AF18),"NA") -> 1.0750776e+09 | AI18: =IFERROR(AG18*100/AG238,"NA") -> 13.164133 | AK18: =IFERROR(AG459*100/AG238,"NA") -> 2.5135495 | AM18: =IFERROR(AG680*100/AG238,"NA") -> 9.2873308
A19: Taxes on goods and services (current LCU) | B19: GC.TAX.GSRV.CN | C19: Belarus | D19: BLR | E19: 1209560 | F19: 2193460 | G19: 4802210 | H19: 7757750 | I19: 32942470 | J19: 101656000 | K19: 178242000 | L19: 251079000 | M19: 370189400 | N19: 543991000 | O19: 738047400 | P19: 1128617900 | Q19: 1270861800 | R19: 1.5231464e+09 | S19: 1397172200 | T19: 1.6701819e+09 | U19: 2495000000 | V19: 4610280000 | W19: 5994690000 | X19: 7529064110 | Y19: 7.8650167e+09 | Z19: 8.7935673e+09 | AA19: 9068217958 | AB19: 1.1020978e+10 | AC19: 1.1753309e+10 | AD19: 1.3111921e+10 | AE19: 1.558478e+10 | AF19: .. | AG19: =IFERROR(AVERAGE(E19:AF19),"NA") -> 3.9647746e+09 | AI19: =IFERROR(AG19*100/AG239,"NA") -> 8.0357778 | AK19: =IFERROR(AG460*100/AG239,"NA") -> 3.1923354 | AM19: =IFERROR(AG681*100/AG239,"NA") -> 0.85928337
